Workbook

Sheet INPUT
A1: . | B1: . | C1: ▸ TRAVEL LOG (raw input) | U1: ▸ TOTALS | Y1: ▸ UNIQUE CITY STAYS | AH1: ▸ UNIQUE COUNTRY STAYS | AQ1: ▸ UNIQUE CONTINENT STAYS | AZ1: ▸ UNIQUE WB STAYS | BI1: ▸ COUNTRY ENTRIES | BQ1: ▸ ALL FLIGHTS | BX1: ▸ HOME STAYS | CC1: Stay Transit | CD1: ▸ TRANSIT STAYS | CI1: Repeated Transit | CJ1: ▸ REPEATED TRANSIT
A2: . | B2: . | C2: =MAX(C5:C1758) | D2: input | E2: input | F2: input | G2: input | H2: input | I2: input | J2: input | K2: CCC | L2: CCC | M2: CCC | N2: fla | O2: fla | P2: fla | Q2: fla | R2: fla | S2: tblHome | U2: =MAX(U5:U2100) | V2: =MAX(V5:V2100) | W2: =MAX(W5:W2100) | Y2: <>AIR | AF2: =MAX(stayCity[yr]) | AO2: =MAX(AN4:AN4999) | AX2: =MAX(AW5:AW5000) | BG2: =MAX(BG5:BG5000) | BK2: =COUNTIF(BK5:BK305,"<>0") | BO2: =COUNTIF(BO5:BO305,"<>0") | CK2: .
A3: . | B3: . | C3: id | D3: city | E3: in | F3: out | G3: flight | H3: home | I3: transit | J3: note | K3: prov | L3: ctry | M3: cont | N3: wb | O3: stay | P3: mth | Q3: yr | R3: dec | S3: notHome | U3: daysAbroad | Y3: ucityStay | Z3: in | AA3: out | AB3: city | AC3: in | AD3: out | AE3: stay | AF3: yr | AH3: uctryStay | AI3: in | AJ3: out | AK3: ctry | AL3: in | AM3: out | AN3: stay | AO3: id | AQ3: ucontStay | AR3: in | AS3: out | AT3: cont | AU3: in | AV3: out | AW3: stay | AX3: id | AZ3: uwb | BA3: in | BB3: out | BC3: wb | BD3: in | BE3: out | BF3: stay | BG3: id | BI3: uctryEntry | BK3: ctry | BL3: yr | BM3: . | BN3: ucontEntry | BO3: cont | BP3: . | BQ3: =MAX(BP5:BP5000) | BR3: outbound | BS3: inbound | BT3: route | BU3: date | BV3: . | BW3: =MAX(BV5:BV5000) | BX3: uhomeStay | BY3: in | BZ3: out | CA3: stay | CB3: . | CC3: =MAX(CB5:CB5000) | CD3: utransitStay | CE3: in | CF3: out | CG3: stay | CH3: . | CI3: =MAX(CH5:CH5000) | CJ3: uTransit | CK3: .
A4: . | B4: . | K4: =IF(raw[[#This Row],[city]]<>"",_xlfn.XLOOKUP($D4,ccc[city],ccc[prov],"-"),"-") | O4: =IF(raw[[#This Row],[out]]=0,0,IF(raw[[#This Row],[out]]=raw[[#This Row],[in]],0.01,raw[[#This Row],[out]]-raw[[#This Row],[in]])) | R4: =INT(raw[[#This Row],[yr]]/10)*10 | S4: =IF(raw[[#This Row],[city]]="","-",IF(raw[[#This Row],[city]]<>_xlfn.XLOOKUP(raw[[#This Row],[home]],homes[home],homes[city],"-"),1,0)) | Y4: {=_xlfn.LET(_xlpm.ct0,raw[city],_xlpm.di0,raw[in],_xlpm.do0,raw[out],_xlpm.m,(_xlpm.ct0<>"AIR")*(_xlpm.ct0<>"Today")*(_xlpm.ct0<>"-")*(_xlpm.di0<>_xlpm.do0),_xlpm.ct,_xlfn._xlws.FILTER(_xlpm.ct0,_xlpm.m),_xlpm.di,_xlfn._xlws.FILTER(_xlpm.di0,_xlpm.m),_xlpm.do,_xlfn._xlws.FILTER(_xlpm.do0,_xlpm.m),_xlpm.n,ROWS(_xlpm.ct),_xlpm.isStart,(_xlfn.SEQUENCE(_xlpm.n)=1)+(_xlpm.ct<>_xlfn.IFNA(INDEX(_xlpm.ct,_xlfn.SEQUENCE(_xlpm.n)-1),"")),_xlpm.idx,_xlfn._xlws.FILTER(_xlfn.SEQUENCE(_xlpm.n),_xlpm.isStart),_xlpm.endIdx,_xlfn.VSTACK(_xlfn.DROP(_xlpm.idx,1),_xlpm.n+1)-1,_xlfn.HSTACK(INDEX(_xlpm.ct,_xlpm.idx),INDEX(_xlpm.di,_xlpm.idx),INDEX(_xlpm.do,_xlpm.endIdx)))} | AB4: {=_xlfn.LET(_xlpm.S,_xlfn.ANCHORARRAY($Y$4),_xlpm.r,ROWS(stayCity[[#Headers],[city]]:stayCity[[#This Row],[city]])-1,IF(_xlpm.r<=ROWS(_xlpm.S),INDEX(_xlpm.S,_xlpm.r,1),""))} | AC4: {=_xlfn.LET(_xlpm.S,_xlfn.ANCHORARRAY($Y$4),_xlpm.r,ROWS(stayCity[[#Headers],[city]]:stayCity[[#This Row],[city]])-1,IF(_xlpm.r<=ROWS(_xlpm.S),INDEX(_xlpm.S,_xlpm.r,2),""))} | AD4: {=_xlfn.LET(_xlpm.S,_xlfn.ANCHORARRAY($Y$4),_xlpm.r,ROWS(stayCity[[#Headers],[city]]:stayCity[[#This Row],[city]])-1,IF(_xlpm.r<=ROWS(_xlpm.S),INDEX(_xlpm.S,_xlpm.r,3),""))} | BL4: =BJ4 | CK4: .
A5: . | B5: . | C5: =IF(raw[[#This Row],[city]]="","-",IF(raw[[#This Row],[city]]="TODAY","-",C4+1)) | D5: SSA | E5: 26170 | F5: 26299 | G5: - | H5: Vitoria Regia | I5: - | J5: - | K5: =IF(raw[[#This Row],[city]]<>"",_xlfn.XLOOKUP($D5,ccc[city],ccc[prov],"-"),"-") | L5: =IF(raw[[#This Row],[city]]<>"",_xlfn.XLOOKUP($D5,ccc[city],ccc[ctry],"-"),"-") | M5: =IF(raw[[#This Row],[city]]<>"",_xlfn.XLOOKUP($D5,ccc[city],ccc[cont],"-"),"-") | N5: =IF(raw[[#This Row],[city]]="","-",IF(raw[[#This Row],[cont]]="B",raw[[#This Row],[cont]],"W")) | O5: =IF(raw[[#This Row],[out]]=0,0,IF(raw[[#This Row],[out]]=raw[[#This Row],[in]],0.01,raw[[#This Row],[out]]-raw[[#This Row],[in]])) | P5: =IF(raw[[#This Row],[in]]=0,0,MONTH(raw[[#This Row],[in]])) | Q5: =IF(raw[[#This Row],[in]]=0,0,YEAR(raw[[#This Row],[in]])) | R5: =INT(raw[[#This Row],[yr]]/10)*10 | S5: =IF(raw[[#This Row],[city]]="","-",IF(raw[[#This Row],[city]]<>_xlfn.XLOOKUP(raw[[#This Row],[home]],homes[home],homes[city],"-"),1,0)) | T5: . | U5: =IF(raw[[#This Row],[wb]]="w",raw[[#This Row],[stay]]+U4,U4) | V5: =IF(raw[[#This Row],[out]]=0,V4,(raw[[#This Row],[out]]-E$5)) | W5: =U5/V5 | X5: . | AB5: {=_xlfn.LET(_xlpm.S,_xlfn.ANCHORARRAY($Y$4),_xlpm.r,ROWS(stayCity[[#Headers],[city]]:stayCity[[#This Row],[city]])-1,IF(_xlpm.r<=ROWS(_xlpm.S),INDEX(_xlpm.S,_xlpm.r,1),""))} | AC5: {=_xlfn.LET(_xlpm.S,_xlfn.ANCHORARRAY($Y$4),_xlpm.r,ROWS(stayCity[[#Headers],[city]]:stayCity[[#This Row],[city]])-1,IF(_xlpm.r<=ROWS(_xlpm.S),INDEX(_xlpm.S,_xlpm.r,2),""))} | AD5: {=_xlfn.LET(_xlpm.S,_xlfn.ANCHORARRAY($Y$4),_xlpm.r,ROWS(stayCity[[#Headers],[city]]:stayCity[[#This Row],[city]])-1,IF(_xlpm.r<=ROWS(_xlpm.S),INDEX(_xlpm.S,_xlpm.r,3),""))} | AE5: =IF(stayCity[[#This Row],[out]]<>"",stayCity[[#This Row],[out]]-stayCity[[#This Row],[in]],"-") | AF5: =IF(Y5="","-",YEAR(stayCity[[#This Row],[in]])) | AG5: . | AH5: {=_xlfn.LET(_xlpm.ct0,raw[ctry],_xlpm.di0,raw[in],_xlpm.do0,raw[out],_xlpm.m,(_xlpm.ct0<>"AIR")*(_xlpm.ct0<>"Today")*(_xlpm.ct0<>"-")*(_xlpm.di0<>_xlpm.do0),_xlpm.ct,_xlfn._xlws.FILTER(_xlpm.ct0,_xlpm.m),_xlpm.di,_xlfn._xlws.FILTER(_xlpm.di0,_xlpm.m),_xlpm.do,_xlfn._xlws.FILTER(_xlpm.do0,_xlpm.m),_xlpm.n,ROWS(_xlpm.ct),_xlpm.isStart,(_xlfn.SEQUENCE(_xlpm.n)=1)+(_xlpm.ct<>_xlfn.IFNA(INDEX(_xlpm.ct,_xlfn.SEQUENCE(_xlpm.n)-1),"")),_xlpm.idx,_xlfn._xlws.FILTER(_xlfn.SEQUENCE(_xlpm.n),_xlpm.isStart),_xlpm.endIdx,_xlfn.VSTACK(_xlfn.DROP(_xlpm.idx,1),_xlpm.n+1)-1,_xlfn.HSTACK(INDEX(_xlpm.ct,_xlpm.idx),INDEX(_xlpm.di,_xlpm.idx),INDEX(_xlpm.do,_xlpm.endIdx)))} | AK5: =IF(AH5="","-",AH5) | AL5: =AI5 | AM5: =AJ5 | AN5: =stayCtry[[#This Row],[out]]-stayCtry[[#This Row],[in]] | AO5: 1 | AP5: . | AQ5: {=_xlfn.LET(_xlpm.ct0,raw[cont],_xlpm.di0,raw[in],_xlpm.do0,raw[out],_xlpm.m,(_xlpm.ct0<>0)*(_xlpm.ct0<>"Today")*(_xlpm.ct0<>"-")*(_xlpm.di0<>_xlpm.do0),_xlpm.ct,_xlfn._xlws.FILTER(_xlpm.ct0,_xlpm.m),_xlpm.di,_xlfn._xlws.FILTER(_xlpm.di0,_xlpm.m),_xlpm.do,_xlfn._xlws.FILTER(_xlpm.do0,_xlpm.m),_xlpm.n,ROWS(_xlpm.ct),_xlpm.isStart,(_xlfn.SEQUENCE(_xlpm.n)=1)+(_xlpm.ct<>_xlfn.IFNA(INDEX(_xlpm.ct,_xlfn.SEQUENCE(_xlpm.n)-1),"")),_xlpm.idx,_xlfn._xlws.FILTER(_xlfn.SEQUENCE(_xlpm.n),_xlpm.isStart),_xlpm.endIdx,_xlfn.VSTACK(_xlfn.DROP(_xlpm.idx,1),_xlpm.n+1)-1,_xlfn.HSTACK(INDEX(_xlpm.ct,_xlpm.idx),INDEX(_xlpm.di,_xlpm.idx),INDEX(_xlpm.do,_xlpm.endIdx)))} | AT5: =AQ5 | AU5: =AR5 | AV5: =AS5 | AW5: =stayCont[[#This Row],[out]]-stayCont[[#This Row],[in]] | AX5: 1 | AY5: . | AZ5: {=_xlfn.LET(_xlpm.ct0,raw[wb],_xlpm.di0,raw[in],_xlpm.do0,raw[out],_xlpm.m,(_xlpm.ct0<>0)*(_xlpm.ct0<>"Today")*(_xlpm.ct0<>"-")*(_xlpm.di0<>_xlpm.do0),_xlpm.ct,_xlfn._xlws.FILTER(_xlpm.ct0,_xlpm.m),_xlpm.di,_xlfn._xlws.FILTER(_xlpm.di0,_xlpm.m),_xlpm.do,_xlfn._xlws.FILTER(_xlpm.do0,_xlpm.m),_xlpm.n,ROWS(_xlpm.ct),_xlpm.isStart,(_xlfn.SEQUENCE(_xlpm.n)=1)+(_xlpm.ct<>_xlfn.IFNA(INDEX(_xlpm.ct,_xlfn.SEQUENCE(_xlpm.n)-1),"")),_xlpm.idx,_xlfn._xlws.FILTER(_xlfn.SEQUENCE(_xlpm.n),_xlpm.isStart),_xlpm.endIdx,_xlfn.VSTACK(_xlfn.DROP(_xlpm.idx,1),_xlpm.n+1)-1,_xlpm.res,_xlfn.HSTACK(INDEX(_xlpm.ct,_xlpm.idx),INDEX(_xlpm.di,_xlpm.idx),INDEX(_xlpm.do,_xlpm.endIdx)),IFERROR(_xlfn._xlws.FILTER(_xlpm.res,INDEX(_xlpm.res,,1)="W"),""))} | BC5: =AZ5 | BD5: =BA5 | BE5: =BB5 | BF5: =stayWB[[#This Row],[out]]-stayWB[[#This Row],[in]] | BG5: 1 | BH5: . | BI5: {=_xlfn.LET(_xlpm.col0,raw[ctry],_xlpm.yr0,raw[yr],_xlpm.val,IFERROR(IF(ISNUMBER(_xlpm.col0),_xlpm.col0,TRIM(_xlpm.col0)),""),_xlpm.mask,(_xlpm.val<>"AIR")*(_xlpm.val<>"")*(_xlpm.val<>0)*(_xlpm.val<>"-"),_xlpm.col,_xlfn._xlws.FILTER(_xlpm.val,_xlpm.mask),_xlpm.yr,_xlfn._xlws.FILTER(_xlpm.yr0,_xlpm.mask),_xlpm.n,ROWS(_xlpm.col),_xlpm.start,(_xlfn.SEQUENCE(_xlpm.n)=1)+(_xlpm.col<>_xlfn.IFNA(INDEX(_xlpm.col,_xlfn.SEQUENCE(_xlpm.n)-1),"")),_xlpm.idx,_xlfn._xlws.FILTER(_xlfn.SEQUENCE(_xlpm.n),_xlpm.start),_xlfn.HSTACK(INDEX(_xlpm.col,_xlpm.idx),INDEX(_xlpm.yr,_xlpm.idx)))} | BJ5: 1971 | BK5: =BI5 | BL5: =BJ5 | BM5: . | BN5: {=_xlfn.LET(_xlpm.col0,raw[cont],_xlpm.val,IFERROR(IF(ISNUMBER(_xlpm.col0),_xlpm.col0,TRIM(_xlpm.col0)),""),_xlpm.mask,(_xlpm.val<>"")*(_xlpm.val<>0)*(_xlpm.val<>"-"),_xlpm.col,_xlfn._xlws.FILTER(_xlpm.val,_xlpm.mask),_xlpm.n,ROWS(_xlpm.col),_xlpm.start,(_xlfn.SEQUENCE(_xlpm.n)=1)+(_xlpm.col<>_xlfn.IFNA(INDEX(_xlpm.col,_xlfn.SEQUENCE(_xlpm.n)-1),"")),_xlpm.idx,_xlfn._xlws.FILTER(_xlfn.SEQUENCE(_xlpm.n),_xlpm.start),INDEX(_xlpm.col,_xlpm.idx))} | BO5: =BN5 | BP5: . | BQ5: 1 | BR5: {=_xlfn.LET(_xlpm.f,raw[flight],_xlpm.city,raw[city],_xlpm.dOut,raw[out], _xlpm.n,ROWS(_xlpm.city), _xlpm.startIdx,_xlfn._xlws.FILTER(_xlfn.SEQUENCE(_xlpm.n),(_xlpm.city<>"AIR")*ISNUMBER(_xlpm.f)*((_xlpm.f=1)+(_xlpm.f=0.01))), _xlpm.nextOk,_xlfn._xlws.FILTER(_xlfn.SEQUENCE(_xlpm.n),_xlpm.city<>"AIR"), _xlpm.toIdx,_xlfn.IFNA(_xlfn.XLOOKUP(_xlpm.startIdx+0.1,_xlpm.nextOk,_xlpm.nextOk,,1),""), _xlpm.fromCity,INDEX(_xlpm.city,_xlpm.startIdx), _xlpm.toCity,_xlfn.IFNA(INDEX(_xlpm.city,_xlpm.toIdx),""), _xlpm.outDate,INDEX(_xlpm.dOut,_xlpm.startIdx), _xlfn._xlws.FILTER(_xlfn.HSTACK(_xlpm.fromCity,_xlpm.toCity,_xlpm.fromCity&"-"&_xlpm.toCity,_xlpm.outDate),_xlpm.toCity<>""))} | BS5: SSA | BT5: Aracaju-SSA | BU5: 29254 | BV5: . | BW5: 1 | BX5: {=_xlfn.LET(_xlpm.ct,raw[home],_xlpm.di,raw[in],_xlpm.do,raw[out],_xlpm.n,ROWS(_xlpm.ct),_xlpm.isStart,(_xlfn.SEQUENCE(_xlpm.n)=1)+(_xlpm.ct<>_xlfn.IFNA(INDEX(_xlpm.ct,_xlfn.SEQUENCE(_xlpm.n)-1),"")),_xlpm.idx,_xlfn._xlws.FILTER(_xlfn.SEQUENCE(_xlpm.n),_xlpm.isStart),_xlpm.nextIdx,_xlfn.VSTACK(_xlfn.DROP(_xlpm.idx,1),_xlpm.n+1),_xlpm.endIdx,_xlpm.nextIdx-1,_xlpm.res,_xlfn.HSTACK(INDEX(_xlpm.ct,_xlpm.idx),INDEX(_xlpm.di,_xlpm.idx),INDEX(_xlpm.do,_xlpm.endIdx)),_xlfn._xlws.FILTER(_xlpm.res,(INDEX(_xlpm.di,_xlpm.idx)<>INDEX(_xlpm.do,_xlpm.endIdx))*(INDEX(_xlpm.ct,_xlpm.idx)<>0)*(INDEX(_xlpm.ct,_xlpm.idx)<>"transit")))} | CA5: =BZ5-BY5 | CB5: . | CC5: 1 | CD5: {=_xlfn.LET(_xlpm.ct,raw[transit],_xlpm.di,raw[in],_xlpm.do,raw[out],_xlpm.n,ROWS(_xlpm.ct),_xlpm.isStart,(_xlfn.SEQUENCE(_xlpm.n)=1)+(_xlpm.ct<>_xlfn.IFNA(INDEX(_xlpm.ct,_xlfn.SEQUENCE(_xlpm.n)-1),"")),_xlpm.idx,_xlfn._xlws.FILTER(_xlfn.SEQUENCE(_xlpm.n),_xlpm.isStart),_xlpm.nextIdx,_xlfn.VSTACK(_xlfn.DROP(_xlpm.idx,1),_xlpm.n+1),_xlpm.endIdx,_xlpm.nextIdx-1,_xlpm.res,_xlfn.HSTACK(INDEX(_xlpm.ct,_xlpm.idx),INDEX(_xlpm.di,_xlpm.idx),INDEX(_xlpm.do,_xlpm.endIdx)),_xlfn._xlws.FILTER(_xlpm.res,(INDEX(_xlpm.di,_xlpm.idx)<>INDEX(_xlpm.do,_xlpm.endIdx))*(INDEX(_xlpm.ct,_xlpm.idx)<>0)*(INDEX(_xlpm.ct,_xlpm.idx)<>"-")))} | CE5: 33587 | CF5: 33594 | CG5: =CF5-CE5 | CH5: . | CI5: 1 | CJ5: {=_xlfn.UNIQUE(CD5:CD300)} | CK5: .
A6: . | B6: . | C6: =IF(raw[[#This Row],[city]]="","-",IF(raw[[#This Row],[city]]="TODAY","-",C5+1)) | D6: SSA | E6: 26299 | F6: 26359 | G6: - | H6: Vitoria Regia | I6: - | J6: REV | K6: =IF(raw[[#This Row],[city]]<>"",_xlfn.XLOOKUP($D6,ccc[city],ccc[prov],"-"),"-") | L6: =IF(raw[[#This Row],[city]]<>"",_xlfn.XLOOKUP($D6,ccc[city],ccc[ctry],"-"),"-") | M6: =IF(raw[[#This Row],[city]]<>"",_xlfn.XLOOKUP($D6,ccc[city],ccc[cont],"-"),"-") | N6: =IF(raw[[#This Row],[city]]="","-",IF(raw[[#This Row],[cont]]="B",raw[[#This Row],[cont]],"W")) | O6: =IF(raw[[#This Row],[out]]=0,0,IF(raw[[#This Row],[out]]=raw[[#This Row],[in]],0.01,raw[[#This Row],[out]]-raw[[#This Row],[in]])) | P6: =IF(raw[[#This Row],[in]]=0,0,MONTH(raw[[#This Row],[in]])) | Q6: =IF(raw[[#This Row],[in]]=0,0,YEAR(raw[[#This Row],[in]])) | R6: =INT(raw[[#This Row],[yr]]/10)*10 | S6: =IF(raw[[#This Row],[city]]="","-",IF(raw[[#This Row],[city]]<>_xlfn.XLOOKUP(raw[[#This Row],[home]],homes[home],homes[city],"-"),1,0)) | T6: . | U6: =IF(raw[[#This Row],[wb]]="w",raw[[#This Row],[stay]]+U5,U5) | V6: =IF(raw[[#This Row],[out]]=0,V5,(raw[[#This Row],[out]]-E$5)) | W6: =U6/V6 | X6: . | AB6: {=_xlfn.LET(_xlpm.S,_xlfn.ANCHORARRAY($Y$4),_xlpm.r,ROWS(stayCity[[#Headers],[city]]:stayCity[[#This Row],[city]])-1,IF(_xlpm.r<=ROWS(_xlpm.S),INDEX(_xlpm.S,_xlpm.r,1),""))} | AC6: {=_xlfn.LET(_xlpm.S,_xlfn.ANCHORARRAY($Y$4),_xlpm.r,ROWS(stayCity[[#Headers],[city]]:stayCity[[#This Row],[city]])-1,IF(_xlpm.r<=ROWS(_xlpm.S),INDEX(_xlpm.S,_xlpm.r,2),""))} | AD6: {=_xlfn.LET(_xlpm.S,_xlfn.ANCHORARRAY($Y$4),_xlpm.r,ROWS(stayCity[[#Headers],[city]]:stayCity[[#This Row],[city]])-1,IF(_xlpm.r<=ROWS(_xlpm.S),INDEX(_xlpm.S,_xlpm.r,3),""))} | AE6: =IF(stayCity[[#This Row],[out]]<>"",stayCity[[#This Row],[out]]-stayCity[[#This Row],[in]],"-") | AF6: =IF(Y6="","-",YEAR(stayCity[[#This Row],[in]])) | AG6: . | AK6: =IF(AH6="","-",AH6) | AL6: =AI6 | AM6: =AJ6 | AN6: =stayCtry[[#This Row],[out]]-stayCtry[[#This Row],[in]] | AO6: =IF(AI6<>"",AO5+1,AO5) | AP6: . | AT6: =AQ6 | AU6: =AR6 | AV6: =AS6 | AW6: =stayCont[[#This Row],[out]]-stayCont[[#This Row],[in]] | AX6: =IF(AR6<>"",AX5+1,AX5) | AY6: . | BC6: =AZ6 | BD6: =BA6 | BE6: =BB6 | BF6: =stayWB[[#This Row],[out]]-stayWB[[#This Row],[in]] | BG6: =IF(BB6<>"",BG5+1,BG5) | BH6: . | BI6: PER | BJ6: 1982 | BK6: =BI6 | BL6: =BJ6 | BM6: . | BN6: Z | BO6: =BN6 | BP6: . | BQ6: =IF(BR6<>"",BQ5+1,BQ5) | BR6: SSA | BS6: Rio | BT6: SSA-Rio | BU6: 29957 | BV6: . | BW6: =IF(BX6<>"",BW5+1,BW5) | CA6: =BZ6-BY6 | CB6: . | CC6: =IF(CD6<>"",CC5+1,CC5) | CD6: Anibal/Vila Mariana | CE6: 33618 | CF6: 33625 | CG6: =CF6-CE6 | CH6: . | CI6: =IF(CJ6<>"",CI5+1,CI5) | CJ6: Anibal/Vila Mariana | CK6: .
A7: . | B7: . | C7: =IF(raw[[#This Row],[city]]="","-",IF(raw[[#This Row],[city]]="TODAY","-",C6+1)) | D7: SSA | E7: 26359 | F7: 26665 | G7: - | H7: Greenfeld | I7: - | J7: - | K7: =IF(raw[[#This Row],[city]]<>"",_xlfn.XLOOKUP($D7,ccc[city],ccc[prov],"-"),"-") | L7: =IF(raw[[#This Row],[city]]<>"",_xlfn.XLOOKUP($D7,ccc[city],ccc[ctry],"-"),"-") | M7: =IF(raw[[#This Row],[city]]<>"",_xlfn.XLOOKUP($D7,ccc[city],ccc[cont],"-"),"-") | N7: =IF(raw[[#This Row],[city]]="","-",IF(raw[[#This Row],[cont]]="B",raw[[#This Row],[cont]],"W")) | O7: =IF(raw[[#This Row],[out]]=0,0,IF(raw[[#This Row],[out]]=raw[[#This Row],[in]],0.01,raw[[#This Row],[out]]-raw[[#This Row],[in]])) | P7: =IF(raw[[#This Row],[in]]=0,0,MONTH(raw[[#This Row],[in]])) | Q7: =IF(raw[[#This Row],[in]]=0,0,YEAR(raw[[#This Row],[in]])) | R7: =INT(raw[[#This Row],[yr]]/10)*10 | S7: =IF(raw[[#This Row],[city]]="","-",IF(raw[[#This Row],[city]]<>_xlfn.XLOOKUP(raw[[#This Row],[home]],homes[home],homes[city],"-"),1,0)) | T7: . | U7: =IF(raw[[#This Row],[wb]]="w",raw[[#This Row],[stay]]+U6,U6) | V7: =IF(raw[[#This Row],[out]]=0,V6,(raw[[#This Row],[out]]-E$5)) | W7: =U7/V7 | X7: . | AB7: {=_xlfn.LET(_xlpm.S,_xlfn.ANCHORARRAY($Y$4),_xlpm.r,ROWS(stayCity[[#Headers],[city]]:stayCity[[#This Row],[city]])-1,IF(_xlpm.r<=ROWS(_xlpm.S),INDEX(_xlpm.S,_xlpm.r,1),""))} | AC7: {=_xlfn.LET(_xlpm.S,_xlfn.ANCHORARRAY($Y$4),_xlpm.r,ROWS(stayCity[[#Headers],[city]]:stayCity[[#This Row],[city]])-1,IF(_xlpm.r<=ROWS(_xlpm.S),INDEX(_xlpm.S,_xlpm.r,2),""))} | AD7: {=_xlfn.LET(_xlpm.S,_xlfn.ANCHORARRAY($Y$4),_xlpm.r,ROWS(stayCity[[#Headers],[city]]:stayCity[[#This Row],[city]])-1,IF(_xlpm.r<=ROWS(_xlpm.S),INDEX(_xlpm.S,_xlpm.r,3),""))} | AE7: =IF(stayCity[[#This Row],[out]]<>"",stayCity[[#This Row],[out]]-stayCity[[#This Row],[in]],"-") | AF7: =IF(Y7="","-",YEAR(stayCity[[#This Row],[in]])) | AG7: . | AK7: =IF(AH7="","-",AH7) | AL7: =AI7 | AM7: =AJ7 | AN7: =stayCtry[[#This Row],[out]]-stayCtry[[#This Row],[in]] | AO7: =IF(AI7<>"",AO6+1,AO6) | AP7: . | AT7: =AQ7 | AU7: =AR7 | AV7: =AS7 | AW7: =stayCont[[#This Row],[out]]-stayCont[[#This Row],[in]] | AX7: =IF(AR7<>"",AX6+1,AX6) | AY7: . | BC7: =AZ7 | BD7: =BA7 | BE7: =BB7 | BF7: =stayWB[[#This Row],[out]]-stayWB[[#This Row],[in]] | BG7: =IF(BB7<>"",BG6+1,BG6) | BH7: . | BI7: MEX | BJ7: 1982 | BK7: =BI7 | BL7: =BJ7 | BM7: . | BN7: S | BO7: =BN7 | BP7: . | BQ7: =IF(BR7<>"",BQ6+1,BQ6) | BR7: Rio | BS7: Lima | BT7: Rio-Lima | BU7: 29957 | BV7: . | BW7: =IF(BX7<>"",BW6+1,BW6) | CA7: =BZ7-BY7 | CB7: . | CC7: =IF(CD7<>"",CC6+1,CC6) | CD7: Anibal/Bela Vista | CE7: 33676 | CF7: 33695 | CG7: =CF7-CE7 | CH7: . | CI7: =IF(CJ7<>"",CI6+1,CI6) | CJ7: Greenfeld | CK7: .
A8: . | B8: . | C8: =IF(raw[[#This Row],[city]]="","-",IF(raw[[#This Row],[city]]="TODAY","-",C7+1)) | D8: SSA | E8: 26665 | F8: 27030 | G8: - | H8: =H7 | I8: - | J8: REV | K8: =IF(raw[[#This Row],[city]]<>"",_xlfn.XLOOKUP($D8,ccc[city],ccc[prov],"-"),"-") | L8: =IF(raw[[#This Row],[city]]<>"",_xlfn.XLOOKUP($D8,ccc[city],ccc[ctry],"-"),"-") | M8: =IF(raw[[#This Row],[city]]<>"",_xlfn.XLOOKUP($D8,ccc[city],ccc[cont],"-"),"-") | N8: =IF(raw[[#This Row],[city]]="","-",IF(raw[[#This Row],[cont]]="B",raw[[#This Row],[cont]],"W")) | O8: =IF(raw[[#This Row],[out]]=0,0,IF(raw[[#This Row],[out]]=raw[[#This Row],[in]],0.01,raw[[#This Row],[out]]-raw[[#This Row],[in]])) | P8: =IF(raw[[#This Row],[in]]=0,0,MONTH(raw[[#This Row],[in]])) | Q8: =IF(raw[[#This Row],[in]]=0,0,YEAR(raw[[#This Row],[in]])) | R8: =INT(raw[[#This Row],[yr]]/10)*10 | S8: =IF(raw[[#This Row],[city]]="","-",IF(raw[[#This Row],[city]]<>_xlfn.XLOOKUP(raw[[#This Row],[home]],homes[home],homes[city],"-"),1,0)) | T8: . | U8: =IF(raw[[#This Row],[wb]]="w",raw[[#This Row],[stay]]+U7,U7) | V8: =IF(raw[[#This Row],[out]]=0,V7,(raw[[#This Row],[out]]-E$5)) | W8: =U8/V8 | X8: . | AB8: {=_xlfn.LET(_xlpm.S,_xlfn.ANCHORARRAY($Y$4),_xlpm.r,ROWS(stayCity[[#Headers],[city]]:stayCity[[#This Row],[city]])-1,IF(_xlpm.r<=ROWS(_xlpm.S),INDEX(_xlpm.S,_xlpm.r,1),""))} | AC8: {=_xlfn.LET(_xlpm.S,_xlfn.ANCHORARRAY($Y$4),_xlpm.r,ROWS(stayCity[[#Headers],[city]]:stayCity[[#This Row],[city]])-1,IF(_xlpm.r<=ROWS(_xlpm.S),INDEX(_xlpm.S,_xlpm.r,2),""))} | AD8: {=_xlfn.LET(_xlpm.S,_xlfn.ANCHORARRAY($Y$4),_xlpm.r,ROWS(stayCity[[#Headers],[city]]:stayCity[[#This Row],[city]])-1,IF(_xlpm.r<=ROWS(_xlpm.S),INDEX(_xlpm.S,_xlpm.r,3),""))} | AE8: =IF(stayCity[[#This Row],[out]]<>"",stayCity[[#This Row],[out]]-stayCity[[#This Row],[in]],"-") | AF8: =IF(Y8="","-",YEAR(stayCity[[#This Row],[in]])) | AG8: . | AK8: =IF(AH8="","-",AH8) | AL8: =AI8 | AM8: =AJ8 | AN8: =stayCtry[[#This Row],[out]]-stayCtry[[#This Row],[in]] | AO8: =IF(AI8<>"",AO7+1,AO7) | AP8: . | AT8: =AQ8 | AU8: =AR8 | AV8: =AS8 | AW8: =stayCont[[#This Row],[out]]-stayCont[[#This Row],[in]] | AX8: =IF(AR8<>"",AX7+1,AX7) | AY8: . | BC8: =AZ8 | BD8: =BA8 | BE8: =BB8 | BF8: =stayWB[[#This Row],[out]]-stayWB[[#This Row],[in]] | BG8: =IF(BB8<>"",BG7+1,BG7) | BH8: . | BI8: USA | BJ8: 1982 | BK8: =BI8 | BL8: =BJ8 | BM8: . | BN8: Z | BO8: =BN8 | BP8: . | BQ8: =IF(BR8<>"",BQ7+1,BQ7) | BR8: Lima | BS8: Cuzco | BT8: Lima-Cuzco | BU8: 29959 | BV8: . | BW8: =IF(BX8<>"",BW7+1,BW7) | CA8: =BZ8-BY8 | CB8: . | CC8: =IF(CD8<>"",CC7+1,CC7) | CD8: Greenfeld | CE8: 33703 | CF8: 33713 | CG8: =CF8-CE8 | CH8: . | CI8: =IF(CJ8<>"",CI7+1,CI7) | CJ8: Meier | CK8: .
A9: . | B9: . | C9: =IF(raw[[#This Row],[city]]="","-",IF(raw[[#This Row],[city]]="TODAY","-",C8+1)) | D9: SSA | E9: 27030 | F9: 27395 | G9: - | H9: =H8 | I9: - | J9: REV | K9: =IF(raw[[#This Row],[city]]<>"",_xlfn.XLOOKUP($D9,ccc[city],ccc[prov],"-"),"-") | L9: =IF(raw[[#This Row],[city]]<>"",_xlfn.XLOOKUP($D9,ccc[city],ccc[ctry],"-"),"-") | M9: =IF(raw[[#This Row],[city]]<>"",_xlfn.XLOOKUP($D9,ccc[city],ccc[cont],"-"),"-") | N9: =IF(raw[[#This Row],[city]]="","-",IF(raw[[#This Row],[cont]]="B",raw[[#This Row],[cont]],"W")) | O9: =IF(raw[[#This Row],[out]]=0,0,IF(raw[[#This Row],[out]]=raw[[#This Row],[in]],0.01,raw[[#This Row],[out]]-raw[[#This Row],[in]])) | P9: =IF(raw[[#This Row],[in]]=0,0,MONTH(raw[[#This Row],[in]])) | Q9: =IF(raw[[#This Row],[in]]=0,0,YEAR(raw[[#This Row],[in]])) | R9: =INT(raw[[#This Row],[yr]]/10)*10 | S9: =IF(raw[[#This Row],[city]]="","-",IF(raw[[#This Row],[city]]<>_xlfn.XLOOKUP(raw[[#This Row],[home]],homes[home],homes[city],"-"),1,0)) | T9: . | U9: =IF(raw[[#This Row],[wb]]="w",raw[[#This Row],[stay]]+U8,U8) | V9: =IF(raw[[#This Row],[out]]=0,V8,(raw[[#This Row],[out]]-E$5)) | W9: =U9/V9 | X9: . | AB9: {=_xlfn.LET(_xlpm.S,_xlfn.ANCHORARRAY($Y$4),_xlpm.r,ROWS(stayCity[[#Headers],[city]]:stayCity[[#This Row],[city]])-1,IF(_xlpm.r<=ROWS(_xlpm.S),INDEX(_xlpm.S,_xlpm.r,1),""))} | AC9: {=_xlfn.LET(_xlpm.S,_xlfn.ANCHORARRAY($Y$4),_xlpm.r,ROWS(stayCity[[#Headers],[city]]:stayCity[[#This Row],[city]])-1,IF(_xlpm.r<=ROWS(_xlpm.S),INDEX(_xlpm.S,_xlpm.r,2),""))} | AD9: {=_xlfn.LET(_xlpm.S,_xlfn.ANCHORARRAY($Y$4),_xlpm.r,ROWS(stayCity[[#Headers],[city]]:stayCity[[#This Row],[city]])-1,IF(_xlpm.r<=ROWS(_xlpm.S),INDEX(_xlpm.S,_xlpm.r,3),""))} | AE9: =IF(stayCity[[#This Row],[out]]<>"",stayCity[[#This Row],[out]]-stayCity[[#This Row],[in]],"-") | AF9: =IF(Y9="","-",YEAR(stayCity[[#This Row],[in]])) | AG9: . | AK9: =IF(AH9="","-",AH9) | AL9: =AI9 | AM9: =AJ9 | AN9: =stayCtry[[#This Row],[out]]-stayCtry[[#This Row],[in]] | AO9: =IF(AI9<>"",AO8+1,AO8) | AP9: . | AT9: =AQ9 | AU9: =AR9 | AV9: =AS9 | AW9: =stayCont[[#This Row],[out]]-stayCont[[#This Row],[in]] | AX9: =IF(AR9<>"",AX8+1,AX8) | AY9: . | BC9: =AZ9 | BD9: =BA9 | BE9: =BB9 | BF9: =stayWB[[#This Row],[out]]-stayWB[[#This Row],[in]] | BG9: =IF(BB9<>"",BG8+1,BG8) | BH9: . | BI9: BRA | BJ9: 1982 | BK9: =BI9 | BL9: =BJ9 | BM9: . | BN9: N | BO9: =BN9 | BP9: . | BQ9: =IF(BR9<>"",BQ8+1,BQ8) | BR9: Cuzco | BS9: Lima | BT9: Cuzco-Lima | BU9: 29961 | BV9: . | BW9: =IF(BX9<>"",BW8+1,BW8) | CA9: =BZ9-BY9 | CB9: . | CC9: =IF(CD9<>"",CC8+1,CC8) | CD9: Greenfeld | CE9: 33786 | CF9: 33821 | CG9: =CF9-CE9 | CH9: . | CI9: =IF(CJ9<>"",CI8+1,CI8) | CJ9: Ondina | CK9: .
A10: . | B10: . | C10: =IF(raw[[#This Row],[city]]="","-",IF(raw[[#This Row],[city]]="TODAY","-",C9+1)) | D10: SSA | E10: 27395 | F10: 27426 | G10: - | H10: =H9 | I10: - | J10: REV | K10: =IF(raw[[#This Row],[city]]<>"",_xlfn.XLOOKUP($D10,ccc[city],ccc[prov],"-"),"-") | L10: =IF(raw[[#This Row],[city]]<>"",_xlfn.XLOOKUP($D10,ccc[city],ccc[ctry],"-"),"-") | M10: =IF(raw[[#This Row],[city]]<>"",_xlfn.XLOOKUP($D10,ccc[city],ccc[cont],"-"),"-") | N10: =IF(raw[[#This Row],[city]]="","-",IF(raw[[#This Row],[cont]]="B",raw[[#This Row],[cont]],"W")) | O10: =IF(raw[[#This Row],[out]]=0,0,IF(raw[[#This Row],[out]]=raw[[#This Row],[in]],0.01,raw[[#This Row],[out]]-raw[[#This Row],[in]])) | P10: =IF(raw[[#This Row],[in]]=0,0,MONTH(raw[[#This Row],[in]])) | Q10: =IF(raw[[#This Row],[in]]=0,0,YEAR(raw[[#This Row],[in]])) | R10: =INT(raw[[#This Row],[yr]]/10)*10 | S10: =IF(raw[[#This Row],[city]]="","-",IF(raw[[#This Row],[city]]<>_xlfn.XLOOKUP(raw[[#This Row],[home]],homes[home],homes[city],"-"),1,0)) | T10: . | U10: =IF(raw[[#This Row],[wb]]="w",raw[[#This Row],[stay]]+U9,U9) | V10: =IF(raw[[#This Row],[out]]=0,V9,(raw[[#This Row],[out]]-E$5)) | W10: =U10/V10 | X10: . | AB10: {=_xlfn.LET(_xlpm.S,_xlfn.ANCHORARRAY($Y$4),_xlpm.r,ROWS(stayCity[[#Headers],[city]]:stayCity[[#This Row],[city]])-1,IF(_xlpm.r<=ROWS(_xlpm.S),INDEX(_xlpm.S,_xlpm.r,1),""))} | AC10: {=_xlfn.LET(_xlpm.S,_xlfn.ANCHORARRAY($Y$4),_xlpm.r,ROWS(stayCity[[#Headers],[city]]:stayCity[[#This Row],[city]])-1,IF(_xlpm.r<=ROWS(_xlpm.S),INDEX(_xlpm.S,_xlpm.r,2),""))} | AD10: {=_xlfn.LET(_xlpm.S,_xlfn.ANCHORARRAY($Y$4),_xlpm.r,ROWS(stayCity[[#Headers],[city]]:stayCity[[#This Row],[city]])-1,IF(_xlpm.r<=ROWS(_xlpm.S),INDEX(_xlpm.S,_xlpm.r,3),""))} | AE10: =IF(stayCity[[#This Row],[out]]<>"",stayCity[[#This Row],[out]]-stayCity[[#This Row],[in]],"-") | AF10: =IF(Y10="","-",YEAR(stayCity[[#This Row],[in]])) | AG10: . | AK10: =IF(AH10="","-",AH10) | AL10: =AI10 | AM10: =AJ10 | AN10: =stayCtry[[#This Row],[out]]-stayCtry[[#This Row],[in]] | AO10: =IF(AI10<>"",AO9+1,AO9) | AP10: . | AT10: =AQ10 | AU10: =AR10 | AV10: =AS10 | AW10: =stayCont[[#This Row],[out]]-stayCont[[#This Row],[in]] | AX10: =IF(AR10<>"",AX9+1,AX9) | AY10: . | BC10: =AZ10 | BD10: =BA10 | BE10: =BB10 | BF10: =stayWB[[#This Row],[out]]-stayWB[[#This Row],[in]] | BG10: =IF(BB10<>"",BG9+1,BG9) | BH10: . | BI10: PRT | BJ10: 1984 | BK10: =BI10 | BL10: =BJ10 | BM10: . | BN10: Z | BO10: =BN10 | BP10: . | BQ10: =IF(BR10<>"",BQ9+1,BQ9) | BR10: Lima | BS10: Mexico City | BT10: Lima-Mexico City | BU10: 29961 | BV10: . | BW10: =IF(BX10<>"",BW9+1,BW9) | CA10: =BZ10-BY10 | CB10: . | CC10: =IF(CD10<>"",CC9+1,CC9) | CD10: Greenfeld | CE10: 33836 | CF10: 33848 | CG10: =CF10-CE10 | CH10: . | CI10: =IF(CJ10<>"",CI9+1,CI9) | CJ10: Salto Grande | CK10: .
A11: . | B11: . | C11: =IF(raw[[#This Row],[city]]="","-",IF(raw[[#This Row],[city]]="TODAY","-",C10+1)) | D11: Porto Seguro | E11: 27426 | F11: 27427 | G11: - | H11: =H10 | I11: - | J11: - | K11: =IF(raw[[#This Row],[city]]<>"",_xlfn.XLOOKUP($D11,ccc[city],ccc[prov],"-"),"-") | L11: =IF(raw[[#This Row],[city]]<>"",_xlfn.XLOOKUP($D11,ccc[city],ccc[ctry],"-"),"-") | M11: =IF(raw[[#This Row],[city]]<>"",_xlfn.XLOOKUP($D11,ccc[city],ccc[cont],"-"),"-") | N11: =IF(raw[[#This Row],[city]]="","-",IF(raw[[#This Row],[cont]]="B",raw[[#This Row],[cont]],"W")) | O11: =IF(raw[[#This Row],[out]]=0,0,IF(raw[[#This Row],[out]]=raw[[#This Row],[in]],0.01,raw[[#This Row],[out]]-raw[[#This Row],[in]])) | P11: =IF(raw[[#This Row],[in]]=0,0,MONTH(raw[[#This Row],[in]])) | Q11: =IF(raw[[#This Row],[in]]=0,0,YEAR(raw[[#This Row],[in]])) | R11: =INT(raw[[#This Row],[yr]]/10)*10 | S11: =IF(raw[[#This Row],[city]]="","-",IF(raw[[#This Row],[city]]<>_xlfn.XLOOKUP(raw[[#This Row],[home]],homes[home],homes[city],"-"),1,0)) | T11: . | U11: =IF(raw[[#This Row],[wb]]="w",raw[[#This Row],[stay]]+U10,U10) | V11: =IF(raw[[#This Row],[out]]=0,V10,(raw[[#This Row],[out]]-E$5)) | W11: =U11/V11 | X11: . | AB11: {=_xlfn.LET(_xlpm.S,_xlfn.ANCHORARRAY($Y$4),_xlpm.r,ROWS(stayCity[[#Headers],[city]]:stayCity[[#This Row],[city]])-1,IF(_xlpm.r<=ROWS(_xlpm.S),INDEX(_xlpm.S,_xlpm.r,1),""))} | AC11: {=_xlfn.LET(_xlpm.S,_xlfn.ANCHORARRAY($Y$4),_xlpm.r,ROWS(stayCity[[#Headers],[city]]:stayCity[[#This Row],[city]])-1,IF(_xlpm.r<=ROWS(_xlpm.S),INDEX(_xlpm.S,_xlpm.r,2),""))} | AD11: {=_xlfn.LET(_xlpm.S,_xlfn.ANCHORARRAY($Y$4),_xlpm.r,ROWS(stayCity[[#Headers],[city]]:stayCity[[#This Row],[city]])-1,IF(_xlpm.r<=ROWS(_xlpm.S),INDEX(_xlpm.S,_xlpm.r,3),""))} | AE11: =IF(stayCity[[#This Row],[out]]<>"",stayCity[[#This Row],[out]]-stayCity[[#This Row],[in]],"-") | AF11: =IF(Y11="","-",YEAR(stayCity[[#This Row],[in]])) | AG11: . | AK11: =IF(AH11="","-",AH11) | AL11: =AI11 | AM11: =AJ11 | AN11: =stayCtry[[#This Row],[out]]-stayCtry[[#This Row],[in]] | AO11: =IF(AI11<>"",AO10+1,AO10) | AP11: . | AT11: =AQ11 | AU11: =AR11 | AV11: =AS11 | AW11: =stayCont[[#This Row],[out]]-stayCont[[#This Row],[in]] | AX11: =IF(AR11<>"",AX10+1,AX10) | AY11: . | BC11: =AZ11 | BD11: =BA11 | BE11: =BB11 | BF11: =stayWB[[#This Row],[out]]-stayWB[[#This Row],[in]] | BG11: =IF(BB11<>"",BG10+1,BG10) | BH11: . | BI11: ITA | BJ11: 1984 | BK11: =BI11 | BL11: =BJ11 | BM11: . | BN11: B | BO11: =BN11 | BP11: . | BQ11: =IF(BR11<>"",BQ10+1,BQ10) | BR11: Mexico City | BS11: New Orleans | BT11: Mexico City-New Orleans | BU11: 29967 | BV11: . | BW11: =IF(BX11<>"",BW10+1,BW10) | CA11: =BZ11-BY11 | CB11: . | CC11: =IF(CD11<>"",CC10+1,CC10) | CD11: Greenfeld | CE11: 33873 | CF11: 33883 | CG11: =CF11-CE11 | CH11: . | CI11: =IF(CJ11<>"",CI10+1,CI10) | CJ11: Thomas/Barnfield | CK11: .
A12: . | B12: . | C12: =IF(raw[[#This Row],[city]]="","-",IF(raw[[#This Row],[city]]="TODAY","-",C11+1)) | D12: Guarapari | E12: 27427 | F12: 27428 | G12: - | H12: =H11 | I12: - | J12: - | K12: =IF(raw[[#This Row],[city]]<>"",_xlfn.XLOOKUP($D12,ccc[city],ccc[prov],"-"),"-") | L12: =IF(raw[[#This Row],[city]]<>"",_xlfn.XLOOKUP($D12,ccc[city],ccc[ctry],"-"),"-") | M12: =IF(raw[[#This Row],[city]]<>"",_xlfn.XLOOKUP($D12,ccc[city],ccc[cont],"-"),"-") | N12: =IF(raw[[#This Row],[city]]="","-",IF(raw[[#This Row],[cont]]="B",raw[[#This Row],[cont]],"W")) | O12: =IF(raw[[#This Row],[out]]=0,0,IF(raw[[#This Row],[out]]=raw[[#This Row],[in]],0.01,raw[[#This Row],[out]]-raw[[#This Row],[in]])) | P12: =IF(raw[[#This Row],[in]]=0,0,MONTH(raw[[#This Row],[in]])) | Q12: =IF(raw[[#This Row],[in]]=0,0,YEAR(raw[[#This Row],[in]])) | R12: =INT(raw[[#This Row],[yr]]/10)*10 | S12: =IF(raw[[#This Row],[city]]="","-",IF(raw[[#This Row],[city]]<>_xlfn.XLOOKUP(raw[[#This Row],[home]],homes[home],homes[city],"-"),1,0)) | T12: . | U12: =IF(raw[[#This Row],[wb]]="w",raw[[#This Row],[stay]]+U11,U11) | V12: =IF(raw[[#This Row],[out]]=0,V11,(raw[[#This Row],[out]]-E$5)) | W12: =U12/V12 | X12: . | AB12: {=_xlfn.LET(_xlpm.S,_xlfn.ANCHORARRAY($Y$4),_xlpm.r,ROWS(stayCity[[#Headers],[city]]:stayCity[[#This Row],[city]])-1,IF(_xlpm.r<=ROWS(_xlpm.S),INDEX(_xlpm.S,_xlpm.r,1),""))} | AC12: {=_xlfn.LET(_xlpm.S,_xlfn.ANCHORARRAY($Y$4),_xlpm.r,ROWS(stayCity[[#Headers],[city]]:stayCity[[#This Row],[city]])-1,IF(_xlpm.r<=ROWS(_xlpm.S),INDEX(_xlpm.S,_xlpm.r,2),""))} | AD12: {=_xlfn.LET(_xlpm.S,_xlfn.ANCHORARRAY($Y$4),_xlpm.r,ROWS(stayCity[[#Headers],[city]]:stayCity[[#This Row],[city]])-1,IF(_xlpm.r<=ROWS(_xlpm.S),INDEX(_xlpm.S,_xlpm.r,3),""))} | AE12: =IF(stayCity[[#This Row],[out]]<>"",stayCity[[#This Row],[out]]-stayCity[[#This Row],[in]],"-") | AF12: =IF(Y12="","-",YEAR(stayCity[[#This Row],[in]])) | AG12: . | AK12: =IF(AH12="","-",AH12) | AL12: =AI12 | AM12: =AJ12 | AN12: =stayCtry[[#This Row],[out]]-stayCtry[[#This Row],[in]] | AO12: =IF(AI12<>"",AO11+1,AO11) | AP12: . | AT12: =AQ12 | AU12: =AR12 | AV12: =AS12 | AW12: =stayCont[[#This Row],[out]]-stayCont[[#This Row],[in]] | AX12: =IF(AR12<>"",AX11+1,AX11) | AY12: . | BC12: =AZ12 | BD12: =BA12 | BE12: =BB12 | BF12: =stayWB[[#This Row],[out]]-stayWB[[#This Row],[in]] | BG12: =IF(BB12<>"",BG11+1,BG11) | BH12: . | BI12: CHE | BJ12: 1984 | BK12: =BI12 | BL12: =BJ12 | BM12: . | BN12: E | BO12: =BN12 | BP12: . | BQ12: =IF(BR12<>"",BQ11+1,BQ11) | BR12: New Orleans | BS12: Orlando | BT12: New Orleans-Orlando | BU12: 29969 | BV12: . | BW12: =IF(BX12<>"",BW11+1,BW11) | CA12: =BZ12-BY12 | CB12: . | CC12: =IF(CD12<>"",CC11+1,CC11) | CD12: Meier | CE12: 33909 | CF12: 33916 | CG12: =CF12-CE12 | CH12: . | CI12: =IF(CJ12<>"",CI11+1,CI11) | CJ12: David's | CK12: .
A13: . | B13: . | C13: =IF(raw[[#This Row],[city]]="","-",IF(raw[[#This Row],[city]]="TODAY","-",C12+1)) | D13: Friburgo | E13: 27428 | F13: 27429 | G13: - | H13: =H12 | I13: - | J13: - | K13: =IF(raw[[#This Row],[city]]<>"",_xlfn.XLOOKUP($D13,ccc[city],ccc[prov],"-"),"-") | L13: =IF(raw[[#This Row],[city]]<>"",_xlfn.XLOOKUP($D13,ccc[city],ccc[ctry],"-"),"-") | M13: =IF(raw[[#This Row],[city]]<>"",_xlfn.XLOOKUP($D13,ccc[city],ccc[cont],"-"),"-") | N13: =IF(raw[[#This Row],[city]]="","-",IF(raw[[#This Row],[cont]]="B",raw[[#This Row],[cont]],"W")) | O13: =IF(raw[[#This Row],[out]]=0,0,IF(raw[[#This Row],[out]]=raw[[#This Row],[in]],0.01,raw[[#This Row],[out]]-raw[[#This Row],[in]])) | P13: =IF(raw[[#This Row],[in]]=0,0,MONTH(raw[[#This Row],[in]])) | Q13: =IF(raw[[#This Row],[in]]=0,0,YEAR(raw[[#This Row],[in]])) | R13: =INT(raw[[#This Row],[yr]]/10)*10 | S13: =IF(raw[[#This Row],[city]]="","-",IF(raw[[#This Row],[city]]<>_xlfn.XLOOKUP(raw[[#This Row],[home]],homes[home],homes[city],"-"),1,0)) | T13: . | U13: =IF(raw[[#This Row],[wb]]="w",raw[[#This Row],[stay]]+U12,U12) | V13: =IF(raw[[#This Row],[out]]=0,V12,(raw[[#This Row],[out]]-E$5)) | W13: =U13/V13 | X13: . | AB13: {=_xlfn.LET(_xlpm.S,_xlfn.ANCHORARRAY($Y$4),_xlpm.r,ROWS(stayCity[[#Headers],[city]]:stayCity[[#This Row],[city]])-1,IF(_xlpm.r<=ROWS(_xlpm.S),INDEX(_xlpm.S,_xlpm.r,1),""))} | AC13: {=_xlfn.LET(_xlpm.S,_xlfn.ANCHORARRAY($Y$4),_xlpm.r,ROWS(stayCity[[#Headers],[city]]:stayCity[[#This Row],[city]])-1,IF(_xlpm.r<=ROWS(_xlpm.S),INDEX(_xlpm.S,_xlpm.r,2),""))} | AD13: {=_xlfn.LET(_xlpm.S,_xlfn.ANCHORARRAY($Y$4),_xlpm.r,ROWS(stayCity[[#Headers],[city]]:stayCity[[#This Row],[city]])-1,IF(_xlpm.r<=ROWS(_xlpm.S),INDEX(_xlpm.S,_xlpm.r,3),""))} | AE13: =IF(stayCity[[#This Row],[out]]<>"",stayCity[[#This Row],[out]]-stayCity[[#This Row],[in]],"-") | AF13: =IF(Y13="","-",YEAR(stayCity[[#This Row],[in]])) | AG13: . | AK13: =IF(AH13="","-",AH13) | AL13: =AI13 | AM13: =AJ13 | AN13: =stayCtry[[#This Row],[out]]-stayCtry[[#This Row],[in]] | AO13: =IF(AI13<>"",AO12+1,AO12) | AP13: . | AT13: =AQ13 | AU13: =AR13 | AV13: =AS13 | AW13: =stayCont[[#This Row],[out]]-stayCont[[#This Row],[in]] | AX13: =IF(AR13<>"",AX12+1,AX12) | AY13: . | BC13: =AZ13 | BD13: =BA13 | BE13: =BB13 | BF13: =stayWB[[#This Row],[out]]-stayWB[[#This Row],[in]] | BG13: =IF(BB13<>"",BG12+1,BG12) | BH13: . | BI13: DEU | BJ13: 1984 | BK13: =BI13 | BL13: =BJ13 | BM13: . | BN13: Z | BO13: =BN13 | BP13: . | BQ13: =IF(BR13<>"",BQ12+1,BQ12) | BR13: Miami | BS13: Manaus | BT13: Miami-Manaus | BU13: 29977 | BV13: . | BW13: =IF(BX13<>"",BW12+1,BW12) | CA13: =BZ13-BY13 | CB13: . | CC13: =IF(CD13<>"",CC12+1,CC12) | CD13: Meier | CE13: 33928 | CF13: 33936 | CG13: =CF13-CE13 | CH13: . | CI13: =IF(CJ13<>"",CI12+1,CI12) | CJ13: Rato/Paulao | CK13: .
A14: . | B14: . | C14: =IF(raw[[#This Row],[city]]="","-",IF(raw[[#This Row],[city]]="TODAY","-",C13+1)) | D14: Rio | E14: 27429 | F14: 27434 | G14: - | H14: =H13 | I14: - | J14: - | K14: =IF(raw[[#This Row],[city]]<>"",_xlfn.XLOOKUP($D14,ccc[city],ccc[prov],"-"),"-") | L14: =IF(raw[[#This Row],[city]]<>"",_xlfn.XLOOKUP($D14,ccc[city],ccc[ctry],"-"),"-") | M14: =IF(raw[[#This Row],[city]]<>"",_xlfn.XLOOKUP($D14,ccc[city],ccc[cont],"-"),"-") | N14: =IF(raw[[#This Row],[city]]="","-",IF(raw[[#This Row],[cont]]="B",raw[[#This Row],[cont]],"W")) | O14: =IF(raw[[#This Row],[out]]=0,0,IF(raw[[#This Row],[out]]=raw[[#This Row],[in]],0.01,raw[[#This Row],[out]]-raw[[#This Row],[in]])) | P14: =IF(raw[[#This Row],[in]]=0,0,MONTH(raw[[#This Row],[in]])) | Q14: =IF(raw[[#This Row],[in]]=0,0,YEAR(raw[[#This Row],[in]])) | R14: =INT(raw[[#This Row],[yr]]/10)*10 | S14: =IF(raw[[#This Row],[city]]="","-",IF(raw[[#This Row],[city]]<>_xlfn.XLOOKUP(raw[[#This Row],[home]],homes[home],homes[city],"-"),1,0)) | T14: . | U14: =IF(raw[[#This Row],[wb]]="w",raw[[#This Row],[stay]]+U13,U13) | V14: =IF(raw[[#This Row],[out]]=0,V13,(raw[[#This Row],[out]]-E$5)) | W14: =U14/V14 | X14: . | AB14: {=_xlfn.LET(_xlpm.S,_xlfn.ANCHORARRAY($Y$4),_xlpm.r,ROWS(stayCity[[#Headers],[city]]:stayCity[[#This Row],[city]])-1,IF(_xlpm.r<=ROWS(_xlpm.S),INDEX(_xlpm.S,_xlpm.r,1),""))} | AC14: {=_xlfn.LET(_xlpm.S,_xlfn.ANCHORARRAY($Y$4),_xlpm.r,ROWS(stayCity[[#Headers],[city]]:stayCity[[#This Row],[city]])-1,IF(_xlpm.r<=ROWS(_xlpm.S),INDEX(_xlpm.S,_xlpm.r,2),""))} | AD14: {=_xlfn.LET(_xlpm.S,_xlfn.ANCHORARRAY($Y$4),_xlpm.r,ROWS(stayCity[[#Headers],[city]]:stayCity[[#This Row],[city]])-1,IF(_xlpm.r<=ROWS(_xlpm.S),INDEX(_xlpm.S,_xlpm.r,3),""))} | AE14: =IF(stayCity[[#This Row],[out]]<>"",stayCity[[#This Row],[out]]-stayCity[[#This Row],[in]],"-") | AF14: =IF(Y14="","-",YEAR(stayCity[[#This Row],[in]])) | AG14: . | AK14: =IF(AH14="","-",AH14) | AL14: =AI14 | AM14: =AJ14 | AN14: =stayCtry[[#This Row],[out]]-stayCtry[[#This Row],[in]] | AO14: =IF(AI14<>"",AO13+1,AO13) | AP14: . | AT14: =AQ14 | AU14: =AR14 | AV14: =AS14 | AW14: =stayCont[[#This Row],[out]]-stayCont[[#This Row],[in]] | AX14: =IF(AR14<>"",AX13+1,AX13) | AY14: . | BC14: =AZ14 | BD14: =BA14 | BE14: =BB14 | BF14: =stayWB[[#This Row],[out]]-stayWB[[#This Row],[in]] | BG14: =IF(BB14<>"",BG13+1,BG13) | BH14: . | BI14: NED | BJ14: 1984 | BK14: =BI14 | BL14: =BJ14 | BM14: . | BN14: N | BO14: =BN14 | BP14: . | BQ14: =IF(BR14<>"",BQ13+1,BQ13) | BR14: Manaus | BS14: Brasilia | BT14: Manaus-Brasilia | BU14: 29981 | BV14: . | BW14: =IF(BX14<>"",BW13+1,BW13) | CA14: =BZ14-BY14 | CB14: . | CC14: =IF(CD14<>"",CC13+1,CC13) | CD14: Greenfeld | CE14: 33937 | CF14: 34029 | CG14: =CF14-CE14 | CH14: . | CI14: =IF(CJ14<>"",CI13+1,CI13) | CJ14: Rato/Republica | CK14: .
A15: . | B15: . | C15: =IF(raw[[#This Row],[city]]="","-",IF(raw[[#This Row],[city]]="TODAY","-",C14+1)) | D15: Petropolis | E15: 27434 | F15: 27444 | G15: - | H15: =H14 | I15: - | J15: - | K15: =IF(raw[[#This Row],[city]]<>"",_xlfn.XLOOKUP($D15,ccc[city],ccc[prov],"-"),"-") | L15: =IF(raw[[#This Row],[city]]<>"",_xlfn.XLOOKUP($D15,ccc[city],ccc[ctry],"-"),"-") | M15: =IF(raw[[#This Row],[city]]<>"",_xlfn.XLOOKUP($D15,ccc[city],ccc[cont],"-"),"-") | N15: =IF(raw[[#This Row],[city]]="","-",IF(raw[[#This Row],[cont]]="B",raw[[#This Row],[cont]],"W")) | O15: =IF(raw[[#This Row],[out]]=0,0,IF(raw[[#This Row],[out]]=raw[[#This Row],[in]],0.01,raw[[#This Row],[out]]-raw[[#This Row],[in]])) | P15: =IF(raw[[#This Row],[in]]=0,0,MONTH(raw[[#This Row],[in]])) | Q15: =IF(raw[[#This Row],[in]]=0,0,YEAR(raw[[#This Row],[in]])) | R15: =INT(raw[[#This Row],[yr]]/10)*10 | S15: =IF(raw[[#This Row],[city]]="","-",IF(raw[[#This Row],[city]]<>_xlfn.XLOOKUP(raw[[#This Row],[home]],homes[home],homes[city],"-"),1,0)) | T15: . | U15: =IF(raw[[#This Row],[wb]]="w",raw[[#This Row],[stay]]+U14,U14) | V15: =IF(raw[[#This Row],[out]]=0,V14,(raw[[#This Row],[out]]-E$5)) | W15: =U15/V15 | X15: . | AB15: {=_xlfn.LET(_xlpm.S,_xlfn.ANCHORARRAY($Y$4),_xlpm.r,ROWS(stayCity[[#Headers],[city]]:stayCity[[#This Row],[city]])-1,IF(_xlpm.r<=ROWS(_xlpm.S),INDEX(_xlpm.S,_xlpm.r,1),""))} | AC15: {=_xlfn.LET(_xlpm.S,_xlfn.ANCHORARRAY($Y$4),_xlpm.r,ROWS(stayCity[[#Headers],[city]]:stayCity[[#This Row],[city]])-1,IF(_xlpm.r<=ROWS(_xlpm.S),INDEX(_xlpm.S,_xlpm.r,2),""))} | AD15: {=_xlfn.LET(_xlpm.S,_xlfn.ANCHORARRAY($Y$4),_xlpm.r,ROWS(stayCity[[#Headers],[city]]:stayCity[[#This Row],[city]])-1,IF(_xlpm.r<=ROWS(_xlpm.S),INDEX(_xlpm.S,_xlpm.r,3),""))} | AE15: =IF(stayCity[[#This Row],[out]]<>"",stayCity[[#This Row],[out]]-stayCity[[#This Row],[in]],"-") | AF15: =IF(Y15="","-",YEAR(stayCity[[#This Row],[in]])) | AG15: . | AK15: =IF(AH15="","-",AH15) | AL15: =AI15 | AM15: =AJ15 | AN15: =stayCtry[[#This Row],[out]]-stayCtry[[#This Row],[in]] | AO15: =IF(AI15<>"",AO14+1,AO14) | AP15: . | AT15: =AQ15 | AU15: =AR15 | AV15: =AS15 | AW15: =stayCont[[#This Row],[out]]-stayCont[[#This Row],[in]] | AX15: =IF(AR15<>"",AX14+1,AX14) | AY15: . | BC15: =AZ15 | BD15: =BA15 | BE15: =BB15 | BF15: =stayWB[[#This Row],[out]]-stayWB[[#This Row],[in]] | BG15: =IF(BB15<>"",BG14+1,BG14) | BH15: . | BI15: FRA | BJ15: 1984 | BK15: =BI15 | BL15: =BJ15 | BM15: . | BN15: Z | BO15: =BN15 | BP15: . | BQ15: =IF(BR15<>"",BQ14+1,BQ14) | BR15: Brasilia | BS15: SSA | BT15: Brasilia-SSA | BU15: 29982 | BV15: . | BW15: =IF(BX15<>"",BW14+1,BW14) | CA15: =BZ15-BY15 | CB15: . | CC15: =IF(CD15<>"",CC14+1,CC14) | CD15: Meier | CE15: 34123 | CF15: 34126 | CG15: =CF15-CE15 | CH15: . | CI15: =IF(CJ15<>"",CI14+1,CI14) | CJ15: CS | CK15: .
A16: . | B16: . | C16: =IF(raw[[#This Row],[city]]="","-",IF(raw[[#This Row],[city]]="TODAY","-",C15+1)) | D16: Rio | E16: 27444 | F16: 27449 | G16: - | H16: =H15 | I16: - | J16: - | K16: =IF(raw[[#This Row],[city]]<>"",_xlfn.XLOOKUP($D16,ccc[city],ccc[prov],"-"),"-") | L16: =IF(raw[[#This Row],[city]]<>"",_xlfn.XLOOKUP($D16,ccc[city],ccc[ctry],"-"),"-") | M16: =IF(raw[[#This Row],[city]]<>"",_xlfn.XLOOKUP($D16,ccc[city],ccc[cont],"-"),"-") | N16: =IF(raw[[#This Row],[city]]="","-",IF(raw[[#This Row],[cont]]="B",raw[[#This Row],[cont]],"W")) | O16: =IF(raw[[#This Row],[out]]=0,0,IF(raw[[#This Row],[out]]=raw[[#This Row],[in]],0.01,raw[[#This Row],[out]]-raw[[#This Row],[in]])) | P16: =IF(raw[[#This Row],[in]]=0,0,MONTH(raw[[#This Row],[in]])) | Q16: =IF(raw[[#This Row],[in]]=0,0,YEAR(raw[[#This Row],[in]])) | R16: =INT(raw[[#This Row],[yr]]/10)*10 | S16: =IF(raw[[#This Row],[city]]="","-",IF(raw[[#This Row],[city]]<>_xlfn.XLOOKUP(raw[[#This Row],[home]],homes[home],homes[city],"-"),1,0)) | T16: . | U16: =IF(raw[[#This Row],[wb]]="w",raw[[#This Row],[stay]]+U15,U15) | V16: =IF(raw[[#This Row],[out]]=0,V15,(raw[[#This Row],[out]]-E$5)) | W16: =U16/V16 | X16: . | AB16: {=_xlfn.LET(_xlpm.S,_xlfn.ANCHORARRAY($Y$4),_xlpm.r,ROWS(stayCity[[#Headers],[city]]:stayCity[[#This Row],[city]])-1,IF(_xlpm.r<=ROWS(_xlpm.S),INDEX(_xlpm.S,_xlpm.r,1),""))} | AC16: {=_xlfn.LET(_xlpm.S,_xlfn.ANCHORARRAY($Y$4),_xlpm.r,ROWS(stayCity[[#Headers],[city]]:stayCity[[#This Row],[city]])-1,IF(_xlpm.r<=ROWS(_xlpm.S),INDEX(_xlpm.S,_xlpm.r,2),""))} | AD16: {=_xlfn.LET(_xlpm.S,_xlfn.ANCHORARRAY($Y$4),_xlpm.r,ROWS(stayCity[[#Headers],[city]]:stayCity[[#This Row],[city]])-1,IF(_xlpm.r<=ROWS(_xlpm.S),INDEX(_xlpm.S,_xlpm.r,3),""))} | AE16: =IF(stayCity[[#This Row],[out]]<>"",stayCity[[#This Row],[out]]-stayCity[[#This Row],[in]],"-") | AF16: =IF(Y16="","-",YEAR(stayCity[[#This Row],[in]])) | AG16: . | AK16: =IF(AH16="","-",AH16) | AL16: =AI16 | AM16: =AJ16 | AN16: =stayCtry[[#This Row],[out]]-stayCtry[[#This Row],[in]] | AO16: =IF(AI16<>"",AO15+1,AO15) | AP16: . | AT16: =AQ16 | AU16: =AR16 | AV16: =AS16 | AW16: =stayCont[[#This Row],[out]]-stayCont[[#This Row],[in]] | AX16: =IF(AR16<>"",AX15+1,AX15) | AY16: . | BC16: =AZ16 | BD16: =BA16 | BE16: =BB16 | BF16: =stayWB[[#This Row],[out]]-stayWB[[#This Row],[in]] | BG16: =IF(BB16<>"",BG15+1,BG15) | BH16: . | BI16: UK | BJ16: 1984 | BK16: =BI16 | BL16: =BJ16 | BM16: . | BN16: B | BO16: =BN16 | BP16: . | BQ16: =IF(BR16<>"",BQ15+1,BQ15) | BR16: SSA | BS16: Lisbon | BT16: SSA-Lisbon | BU16: 30713 | BV16: . | BW16: =IF(BX16<>"",BW15+1,BW15) | CA16: =BZ16-BY16 | CB16: . | CC16: =IF(CD16<>"",CC15+1,CC15) | CD16: Meier | CE16: 34131 | CF16: 34135 | CG16: =CF16-CE16 | CH16: . | CI16: =IF(CJ16<>"",CI15+1,CI15) | CJ16: Hampstead | CK16: .
A17: . | B17: . | C17: =IF(raw[[#This Row],[city]]="","-",IF(raw[[#This Row],[city]]="TODAY","-",C16+1)) | D17: ROAD | E17: 27449 | F17: 27450 | G17: - | H17: =H16 | I17: - | J17: - | K17: =IF(raw[[#This Row],[city]]<>"",_xlfn.XLOOKUP($D17,ccc[city],ccc[prov],"-"),"-") | L17: =IF(raw[[#This Row],[city]]<>"",_xlfn.XLOOKUP($D17,ccc[city],ccc[ctry],"-"),"-") | M17: =IF(raw[[#This Row],[city]]<>"",_xlfn.XLOOKUP($D17,ccc[city],ccc[cont],"-"),"-") | N17: =IF(raw[[#This Row],[city]]="","-",IF(raw[[#This Row],[cont]]="B",raw[[#This Row],[cont]],"W")) | O17: =IF(raw[[#This Row],[out]]=0,0,IF(raw[[#This Row],[out]]=raw[[#This Row],[in]],0.01,raw[[#This Row],[out]]-raw[[#This Row],[in]])) | P17: =IF(raw[[#This Row],[in]]=0,0,MONTH(raw[[#This Row],[in]])) | Q17: =IF(raw[[#This Row],[in]]=0,0,YEAR(raw[[#This Row],[in]])) | R17: =INT(raw[[#This Row],[yr]]/10)*10 | S17: =IF(raw[[#This Row],[city]]="","-",IF(raw[[#This Row],[city]]<>_xlfn.XLOOKUP(raw[[#This Row],[home]],homes[home],homes[city],"-"),1,0)) | T17: . | U17: =IF(raw[[#This Row],[wb]]="w",raw[[#This Row],[stay]]+U16,U16) | V17: =IF(raw[[#This Row],[out]]=0,V16,(raw[[#This Row],[out]]-E$5)) | W17: =U17/V17 | X17: . | AB17: {=_xlfn.LET(_xlpm.S,_xlfn.ANCHORARRAY($Y$4),_xlpm.r,ROWS(stayCity[[#Headers],[city]]:stayCity[[#This Row],[city]])-1,IF(_xlpm.r<=ROWS(_xlpm.S),INDEX(_xlpm.S,_xlpm.r,1),""))} | AC17: {=_xlfn.LET(_xlpm.S,_xlfn.ANCHORARRAY($Y$4),_xlpm.r,ROWS(stayCity[[#Headers],[city]]:stayCity[[#This Row],[city]])-1,IF(_xlpm.r<=ROWS(_xlpm.S),INDEX(_xlpm.S,_xlpm.r,2),""))} | AD17: {=_xlfn.LET(_xlpm.S,_xlfn.ANCHORARRAY($Y$4),_xlpm.r,ROWS(stayCity[[#Headers],[city]]:stayCity[[#This Row],[city]])-1,IF(_xlpm.r<=ROWS(_xlpm.S),INDEX(_xlpm.S,_xlpm.r,3),""))} | AE17: =IF(stayCity[[#This Row],[out]]<>"",stayCity[[#This Row],[out]]-stayCity[[#This Row],[in]],"-") | AF17: =IF(Y17="","-",YEAR(stayCity[[#This Row],[in]])) | AG17: . | AK17: =IF(AH17="","-",AH17) | AL17: =AI17 | AM17: =AJ17 | AN17: =stayCtry[[#This Row],[out]]-stayCtry[[#This Row],[in]] | AO17: =IF(AI17<>"",AO16+1,AO16) | AP17: . | AT17: =AQ17 | AU17: =AR17 | AV17: =AS17 | AW17: =stayCont[[#This Row],[out]]-stayCont[[#This Row],[in]] | AX17: =IF(AR17<>"",AX16+1,AX16) | AY17: . | BC17: =AZ17 | BD17: =BA17 | BE17: =BB17 | BF17: =stayWB[[#This Row],[out]]-stayWB[[#This Row],[in]] | BG17: =IF(BB17<>"",BG16+1,BG16) | BH17: . | BI17: USA | BJ17: 1984 | BK17: =BI17 | BL17: =BJ17 | BM17: . | BN17: Z | BO17: =BN17 | BP17: . | BQ17: =IF(BR17<>"",BQ16+1,BQ16) | BR17: Lisbon | BS17: Rome | BT17: Lisbon-Rome | BU17: 30714 | BV17: . | BW17: =IF(BX17<>"",BW16+1,BW16) | CA17: =BZ17-BY17 | CB17: . | CC17: =IF(CD17<>"",CC16+1,CC16) | CD17: Meier | CE17: 34140 | CF17: 34148 | CG17: =CF17-CE17 | CH17: . | CI17: =IF(CJ17<>"",CI16+1,CI16) | CJ17: Mauricio | CK17: .
A18: . | B18: . | C18: =IF(raw[[#This Row],[city]]="","-",IF(raw[[#This Row],[city]]="TODAY","-",C17+1)) | D18: SSA | E18: 27450 | F18: 27748 | G18: - | H18: =H17 | I18: - | J18: - | K18: =IF(raw[[#This Row],[city]]<>"",_xlfn.XLOOKUP($D18,ccc[city],ccc[prov],"-"),"-") | L18: =IF(raw[[#This Row],[city]]<>"",_xlfn.XLOOKUP($D18,ccc[city],ccc[ctry],"-"),"-") | M18: =IF(raw[[#This Row],[city]]<>"",_xlfn.XLOOKUP($D18,ccc[city],ccc[cont],"-"),"-") | N18: =IF(raw[[#This Row],[city]]="","-",IF(raw[[#This Row],[cont]]="B",raw[[#This Row],[cont]],"W")) | O18: =IF(raw[[#This Row],[out]]=0,0,IF(raw[[#This Row],[out]]=raw[[#This Row],[in]],0.01,raw[[#This Row],[out]]-raw[[#This Row],[in]])) | P18: =IF(raw[[#This Row],[in]]=0,0,MONTH(raw[[#This Row],[in]])) | Q18: =IF(raw[[#This Row],[in]]=0,0,YEAR(raw[[#This Row],[in]])) | R18: =INT(raw[[#This Row],[yr]]/10)*10 | S18: =IF(raw[[#This Row],[city]]="","-",IF(raw[[#This Row],[city]]<>_xlfn.XLOOKUP(raw[[#This Row],[home]],homes[home],homes[city],"-"),1,0)) | T18: . | U18: =IF(raw[[#This Row],[wb]]="w",raw[[#This Row],[stay]]+U17,U17) | V18: =IF(raw[[#This Row],[out]]=0,V17,(raw[[#This Row],[out]]-E$5)) | W18: =U18/V18 | X18: . | AB18: {=_xlfn.LET(_xlpm.S,_xlfn.ANCHORARRAY($Y$4),_xlpm.r,ROWS(stayCity[[#Headers],[city]]:stayCity[[#This Row],[city]])-1,IF(_xlpm.r<=ROWS(_xlpm.S),INDEX(_xlpm.S,_xlpm.r,1),""))} | AC18: {=_xlfn.LET(_xlpm.S,_xlfn.ANCHORARRAY($Y$4),_xlpm.r,ROWS(stayCity[[#Headers],[city]]:stayCity[[#This Row],[city]])-1,IF(_xlpm.r<=ROWS(_xlpm.S),INDEX(_xlpm.S,_xlpm.r,2),""))} | AD18: {=_xlfn.LET(_xlpm.S,_xlfn.ANCHORARRAY($Y$4),_xlpm.r,ROWS(stayCity[[#Headers],[city]]:stayCity[[#This Row],[city]])-1,IF(_xlpm.r<=ROWS(_xlpm.S),INDEX(_xlpm.S,_xlpm.r,3),""))} | AE18: =IF(stayCity[[#This Row],[out]]<>"",stayCity[[#This Row],[out]]-stayCity[[#This Row],[in]],"-") | AF18: =IF(Y18="","-",YEAR(stayCity[[#This Row],[in]])) | AG18: . | AK18: =IF(AH18="","-",AH18) | AL18: =AI18 | AM18: =AJ18 | AN18: =stayCtry[[#This Row],[out]]-stayCtry[[#This Row],[in]] | AO18: =IF(AI18<>"",AO17+1,AO17) | AP18: . | AT18: =AQ18 | AU18: =AR18 | AV18: =AS18 | AW18: =stayCont[[#This Row],[out]]-stayCont[[#This Row],[in]] | AX18: =IF(AR18<>"",AX17+1,AX17) | AY18: . | BC18: =AZ18 | BD18: =BA18 | BE18: =BB18 | BF18: =stayWB[[#This Row],[out]]-stayWB[[#This Row],[in]] | BG18: =IF(BB18<>"",BG17+1,BG17) | BH18: . | BI18: BRA | BJ18: 1984 | BK18: =BI18 | BL18: =BJ18 | BM18: . | BN18: E | BO18: =BN18 | BP18: . | BQ18: =IF(BR18<>"",BQ17+1,BQ17) | BR18: London | BS18: NYC | BT18: London-NYC | BU18: 30740 | BV18: . | BW18: =IF(BX18<>"",BW17+1,BW17) | CA18: =BZ18-BY18 | CB18: . | CC18: =IF(CD18<>"",CC17+1,CC17) | CD18: Greenfeld | CE18: 34151 | CF18: 34186 | CG18: =CF18-CE18 | CH18: . | CI18: =IF(CJ18<>"",CI17+1,CI17) | CJ18: Casa Branca | CK18: .
A19: . | B19: . | C19: =IF(raw[[#This Row],[city]]="","-",IF(raw[[#This Row],[city]]="TODAY","-",C18+1)) | D19: ROAD | E19: 27748 | F19: 27749 | G19: - | H19: =H18 | I19: - | J19: - | K19: =IF(raw[[#This Row],[city]]<>"",_xlfn.XLOOKUP($D19,ccc[city],ccc[prov],"-"),"-") | L19: =IF(raw[[#This Row],[city]]<>"",_xlfn.XLOOKUP($D19,ccc[city],ccc[ctry],"-"),"-") | M19: =IF(raw[[#This Row],[city]]<>"",_xlfn.XLOOKUP($D19,ccc[city],ccc[cont],"-"),"-") | N19: =IF(raw[[#This Row],[city]]="","-",IF(raw[[#This Row],[cont]]="B",raw[[#This Row],[cont]],"W")) | O19: =IF(raw[[#This Row],[out]]=0,0,IF(raw[[#This Row],[out]]=raw[[#This Row],[in]],0.01,raw[[#This Row],[out]]-raw[[#This Row],[in]])) | P19: =IF(raw[[#This Row],[in]]=0,0,MONTH(raw[[#This Row],[in]])) | Q19: =IF(raw[[#This Row],[in]]=0,0,YEAR(raw[[#This Row],[in]])) | R19: =INT(raw[[#This Row],[yr]]/10)*10 | S19: =IF(raw[[#This Row],[city]]="","-",IF(raw[[#This Row],[city]]<>_xlfn.XLOOKUP(raw[[#This Row],[home]],homes[home],homes[city],"-"),1,0)) | T19: . | U19: =IF(raw[[#This Row],[wb]]="w",raw[[#This Row],[stay]]+U18,U18) | V19: =IF(raw[[#This Row],[out]]=0,V18,(raw[[#This Row],[out]]-E$5)) | W19: =U19/V19 | X19: . | AB19: {=_xlfn.LET(_xlpm.S,_xlfn.ANCHORARRAY($Y$4),_xlpm.r,ROWS(stayCity[[#Headers],[city]]:stayCity[[#This Row],[city]])-1,IF(_xlpm.r<=ROWS(_xlpm.S),INDEX(_xlpm.S,_xlpm.r,1),""))} | AC19: {=_xlfn.LET(_xlpm.S,_xlfn.ANCHORARRAY($Y$4),_xlpm.r,ROWS(stayCity[[#Headers],[city]]:stayCity[[#This Row],[city]])-1,IF(_xlpm.r<=ROWS(_xlpm.S),INDEX(_xlpm.S,_xlpm.r,2),""))} | AD19: {=_xlfn.LET(_xlpm.S,_xlfn.ANCHORARRAY($Y$4),_xlpm.r,ROWS(stayCity[[#Headers],[city]]:stayCity[[#This Row],[city]])-1,IF(_xlpm.r<=ROWS(_xlpm.S),INDEX(_xlpm.S,_xlpm.r,3),""))} | AE19: =IF(stayCity[[#This Row],[out]]<>"",stayCity[[#This Row],[out]]-stayCity[[#This Row],[in]],"-") | AF19: =IF(Y19="","-",YEAR(stayCity[[#This Row],[in]])) | AG19: . | AK19: =IF(AH19="","-",AH19) | AL19: =AI19 | AM19: =AJ19 | AN19: =stayCtry[[#This Row],[out]]-stayCtry[[#This Row],[in]] | AO19: =IF(AI19<>"",AO18+1,AO18) | AP19: . | AT19: =AQ19 | AU19: =AR19 | AV19: =AS19 | AW19: =stayCont[[#This Row],[out]]-stayCont[[#This Row],[in]] | AX19: =IF(AR19<>"",AX18+1,AX18) | AY19: . | BC19: =AZ19 | BD19: =BA19 | BE19: =BB19 | BF19: =stayWB[[#This Row],[out]]-stayWB[[#This Row],[in]] | BG19: =IF(BB19<>"",BG18+1,BG18) | BH19: . | BI19: FRA | BJ19: 1987 | BK19: =BI19 | BL19: =BJ19 | BM19: . | BN19: Z | BO19: =BN19 | BP19: . | BQ19: =IF(BR19<>"",BQ18+1,BQ18) | BR19: NYC | BS19: Washington | BT19: NYC-Washington | BU19: 30745 | BV19: . | BW19: =IF(BX19<>"",BW18+1,BW18) | CA19: =BZ19-BY19 | CB19: . | CC19: =IF(CD19<>"",CC18+1,CC18) | CD19: Greenfeld | CE19: 34200 | CF19: 34213 | CG19: =CF19-CE19 | CH19: . | CI19: =IF(CJ19<>"",CI18+1,CI18) | CJ19: Cunha/Guto | CK19: .
... A58: . | B58: . | C58: =IF(raw[[#This Row],[city]]="","-",IF(raw[[#This Row],[city]]="TODAY","-",C57+1)) | D58: SSA | E58: 29252 | F58: 29253 | G58: - | H58: =H57 | I58: - | J58: - | K58: =IF(raw[[#This Row],[city]]<>"",_xlfn.XLOOKUP($D58,ccc[city],ccc[prov],"-"),"-") | L58: =IF(raw[[#This Row],[city]]<>"",_xlfn.XLOOKUP($D58,ccc[city],ccc[ctry],"-"),"-") | M58: =IF(raw[[#This Row],[city]]<>"",_xlfn.XLOOKUP($D58,ccc[city],ccc[cont],"-"),"-") | N58: =IF(raw[[#This Row],[city]]="","-",IF(raw[[#This Row],[cont]]="B",raw[[#This Row],[cont]],"W")) | O58: =IF(raw[[#This Row],[out]]=0,0,IF(raw[[#This Row],[out]]=raw[[#This Row],[in]],0.01,raw[[#This Row],[out]]-raw[[#This Row],[in]])) | P58: =IF(raw[[#This Row],[in]]=0,0,MONTH(raw[[#This Row],[in]])) | Q58: =IF(raw[[#This Row],[in]]=0,0,YEAR(raw[[#This Row],[in]])) | R58: =INT(raw[[#This Row],[yr]]/10)*10 | S58: =IF(raw[[#This Row],[city]]="","-",IF(raw[[#This Row],[city]]<>_xlfn.XLOOKUP(raw[[#This Row],[home]],homes[home],homes[city],"-"),1,0)) | T58: . | U58: =IF(raw[[#This Row],[wb]]="w",raw[[#This Row],[stay]]+U57,U57) | V58: =IF(raw[[#This Row],[out]]=0,V57,(raw[[#This Row],[out]]-E$5)) | W58: =U58/V58 | X58: . | AB58: {=_xlfn.LET(_xlpm.S,_xlfn.ANCHORARRAY($Y$4),_xlpm.r,ROWS(stayCity[[#Headers],[city]]:stayCity[[#This Row],[city]])-1,IF(_xlpm.r<=ROWS(_xlpm.S),INDEX(_xlpm.S,_xlpm.r,1),""))} | AC58: {=_xlfn.LET(_xlpm.S,_xlfn.ANCHORARRAY($Y$4),_xlpm.r,ROWS(stayCity[[#Headers],[city]]:stayCity[[#This Row],[city]])-1,IF(_xlpm.r<=ROWS(_xlpm.S),INDEX(_xlpm.S,_xlpm.r,2),""))} | AD58: {=_xlfn.LET(_xlpm.S,_xlfn.ANCHORARRAY($Y$4),_xlpm.r,ROWS(stayCity[[#Headers],[city]]:stayCity[[#This Row],[city]])-1,IF(_xlpm.r<=ROWS(_xlpm.S),INDEX(_xlpm.S,_xlpm.r,3),""))} | AE58: =IF(stayCity[[#This Row],[out]]<>"",stayCity[[#This Row],[out]]-stayCity[[#This Row],[in]],"-") | AF58: =IF(Y58="","-",YEAR(stayCity[[#This Row],[in]])) | AG58: . | AK58: =IF(AH58="","-",AH58) | AL58: =AI58 | AM58: =AJ58 | AN58: =stayCtry[[#This Row],[out]]-stayCtry[[#This Row],[in]] | AO58: =IF(AI58<>"",AO57+1,AO57) | AP58: . | AT58: =AQ58 | AU58: =AR58 | AV58: =AS58 | AW58: =stayCont[[#This Row],[out]]-stayCont[[#This Row],[in]] | AX58: =IF(AR58<>"",AX57+1,AX57) | AY58: . | BC58: =AZ58 | BD58: =BA58 | BE58: =BB58 | BF58: =stayWB[[#This Row],[out]]-stayWB[[#This Row],[in]] | BG58: =IF(BB58<>"",BG57+1,BG57) | BH58: . | BI58: BRA | BJ58: 1996 | BK58: =BI58 | BL58: =BJ58 | BM58: . | BN58: E | BO58: =BN58 | BP58: . | BQ58: =IF(BR58<>"",BQ57+1,BQ57) | BR58: SP | BS58: SSA | BT58: SP-SSA | BU58: 34669 | BV58: . | BW58: =IF(BX58<>"",BW57+1,BW57) | CA58: =BZ58-BY58 | CB58: . | CC58: =IF(CD58<>"",CC57+1,CC57) | CD58: Guaecá | CE58: 37344 | CF58: 37347 | CG58: =CF58-CE58 | CH58: . | CI58: =IF(CJ58<>"",CI57+1,CI57) | CJ58: Mike | CK58: .
A59: . | B59: . | C59: =IF(raw[[#This Row],[city]]="","-",IF(raw[[#This Row],[city]]="TODAY","-",C58+1)) | D59: Aracaju | E59: 29253 | F59: 29254 | G59: 1 | H59: =H58 | I59: - | J59: - | K59: =IF(raw[[#This Row],[city]]<>"",_xlfn.XLOOKUP($D59,ccc[city],ccc[prov],"-"),"-") | L59: =IF(raw[[#This Row],[city]]<>"",_xlfn.XLOOKUP($D59,ccc[city],ccc[ctry],"-"),"-") | M59: =IF(raw[[#This Row],[city]]<>"",_xlfn.XLOOKUP($D59,ccc[city],ccc[cont],"-"),"-") | N59: =IF(raw[[#This Row],[city]]="","-",IF(raw[[#This Row],[cont]]="B",raw[[#This Row],[cont]],"W")) | O59: =IF(raw[[#This Row],[out]]=0,0,IF(raw[[#This Row],[out]]=raw[[#This Row],[in]],0.01,raw[[#This Row],[out]]-raw[[#This Row],[in]])) | P59: =IF(raw[[#This Row],[in]]=0,0,MONTH(raw[[#This Row],[in]])) | Q59: =IF(raw[[#This Row],[in]]=0,0,YEAR(raw[[#This Row],[in]])) | R59: =INT(raw[[#This Row],[yr]]/10)*10 | S59: =IF(raw[[#This Row],[city]]="","-",IF(raw[[#This Row],[city]]<>_xlfn.XLOOKUP(raw[[#This Row],[home]],homes[home],homes[city],"-"),1,0)) | T59: . | U59: =IF(raw[[#This Row],[wb]]="w",raw[[#This Row],[stay]]+U58,U58) | V59: =IF(raw[[#This Row],[out]]=0,V58,(raw[[#This Row],[out]]-E$5)) | W59: =U59/V59 | X59: . | AB59: {=_xlfn.LET(_xlpm.S,_xlfn.ANCHORARRAY($Y$4),_xlpm.r,ROWS(stayCity[[#Headers],[city]]:stayCity[[#This Row],[city]])-1,IF(_xlpm.r<=ROWS(_xlpm.S),INDEX(_xlpm.S,_xlpm.r,1),""))} | AC59: {=_xlfn.LET(_xlpm.S,_xlfn.ANCHORARRAY($Y$4),_xlpm.r,ROWS(stayCity[[#Headers],[city]]:stayCity[[#This Row],[city]])-1,IF(_xlpm.r<=ROWS(_xlpm.S),INDEX(_xlpm.S,_xlpm.r,2),""))} | AD59: {=_xlfn.LET(_xlpm.S,_xlfn.ANCHORARRAY($Y$4),_xlpm.r,ROWS(stayCity[[#Headers],[city]]:stayCity[[#This Row],[city]])-1,IF(_xlpm.r<=ROWS(_xlpm.S),INDEX(_xlpm.S,_xlpm.r,3),""))} | AE59: =IF(stayCity[[#This Row],[out]]<>"",stayCity[[#This Row],[out]]-stayCity[[#This Row],[in]],"-") | AF59: =IF(Y59="","-",YEAR(stayCity[[#This Row],[in]])) | AG59: . | AK59: =IF(AH59="","-",AH59) | AL59: =AI59 | AM59: =AJ59 | AN59: =stayCtry[[#This Row],[out]]-stayCtry[[#This Row],[in]] | AO59: =IF(AI59<>"",AO58+1,AO58) | AP59: . | AT59: =AQ59 | AU59: =AR59 | AV59: =AS59 | AW59: =stayCont[[#This Row],[out]]-stayCont[[#This Row],[in]] | AX59: =IF(AR59<>"",AX58+1,AX58) | AY59: . | BC59: =AZ59 | BD59: =BA59 | BE59: =BB59 | BF59: =stayWB[[#This Row],[out]]-stayWB[[#This Row],[in]] | BG59: =IF(BB59<>"",BG58+1,BG58) | BH59: . | BI59: DEU | BJ59: 1997 | BK59: =BI59 | BL59: =BJ59 | BM59: . | BN59: N | BO59: =BN59 | BP59: . | BQ59: =IF(BR59<>"",BQ58+1,BQ58) | BR59: SSA | BS59: Lisbon | BT59: SSA-Lisbon | BU59: 34727 | BV59: . | BW59: =IF(BX59<>"",BW58+1,BW58) | CA59: =BZ59-BY59 | CB59: . | CC59: =IF(CD59<>"",CC58+1,CC58) | CD59: Ondina | CE59: 37423 | CF59: 37427 | CG59: =CF59-CE59 | CH59: . | CI59: =IF(CJ59<>"",CI58+1,CI58) | CJ59: Holiday Inn/Airbnb | CK59: .
A60: . | B60: . | C60: =IF(raw[[#This Row],[city]]="","-",IF(raw[[#This Row],[city]]="TODAY","-",C59+1)) | D60: SSA | E60: 29254 | F60: 29587 | G60: - | H60: =H59 | I60: - | J60: - | K60: =IF(raw[[#This Row],[city]]<>"",_xlfn.XLOOKUP($D60,ccc[city],ccc[prov],"-"),"-") | L60: =IF(raw[[#This Row],[city]]<>"",_xlfn.XLOOKUP($D60,ccc[city],ccc[ctry],"-"),"-") | M60: =IF(raw[[#This Row],[city]]<>"",_xlfn.XLOOKUP($D60,ccc[city],ccc[cont],"-"),"-") | N60: =IF(raw[[#This Row],[city]]="","-",IF(raw[[#This Row],[cont]]="B",raw[[#This Row],[cont]],"W")) | O60: =IF(raw[[#This Row],[out]]=0,0,IF(raw[[#This Row],[out]]=raw[[#This Row],[in]],0.01,raw[[#This Row],[out]]-raw[[#This Row],[in]])) | P60: =IF(raw[[#This Row],[in]]=0,0,MONTH(raw[[#This Row],[in]])) | Q60: =IF(raw[[#This Row],[in]]=0,0,YEAR(raw[[#This Row],[in]])) | R60: =INT(raw[[#This Row],[yr]]/10)*10 | S60: =IF(raw[[#This Row],[city]]="","-",IF(raw[[#This Row],[city]]<>_xlfn.XLOOKUP(raw[[#This Row],[home]],homes[home],homes[city],"-"),1,0)) | T60: . | U60: =IF(raw[[#This Row],[wb]]="w",raw[[#This Row],[stay]]+U59,U59) | V60: =IF(raw[[#This Row],[out]]=0,V59,(raw[[#This Row],[out]]-E$5)) | W60: =U60/V60 | X60: . | AB60: {=_xlfn.LET(_xlpm.S,_xlfn.ANCHORARRAY($Y$4),_xlpm.r,ROWS(stayCity[[#Headers],[city]]:stayCity[[#This Row],[city]])-1,IF(_xlpm.r<=ROWS(_xlpm.S),INDEX(_xlpm.S,_xlpm.r,1),""))} | AC60: {=_xlfn.LET(_xlpm.S,_xlfn.ANCHORARRAY($Y$4),_xlpm.r,ROWS(stayCity[[#Headers],[city]]:stayCity[[#This Row],[city]])-1,IF(_xlpm.r<=ROWS(_xlpm.S),INDEX(_xlpm.S,_xlpm.r,2),""))} | AD60: {=_xlfn.LET(_xlpm.S,_xlfn.ANCHORARRAY($Y$4),_xlpm.r,ROWS(stayCity[[#Headers],[city]]:stayCity[[#This Row],[city]])-1,IF(_xlpm.r<=ROWS(_xlpm.S),INDEX(_xlpm.S,_xlpm.r,3),""))} | AE60: =IF(stayCity[[#This Row],[out]]<>"",stayCity[[#This Row],[out]]-stayCity[[#This Row],[in]],"-") | AF60: =IF(Y60="","-",YEAR(stayCity[[#This Row],[in]])) | AG60: . | AK60: =IF(AH60="","-",AH60) | AL60: =AI60 | AM60: =AJ60 | AN60: =stayCtry[[#This Row],[out]]-stayCtry[[#This Row],[in]] | AO60: =IF(AI60<>"",AO59+1,AO59) | AP60: . | AT60: =AQ60 | AU60: =AR60 | AV60: =AS60 | AW60: =stayCont[[#This Row],[out]]-stayCont[[#This Row],[in]] | AX60: =IF(AR60<>"",AX59+1,AX59) | AY60: . | BC60: =AZ60 | BD60: =BA60 | BE60: =BB60 | BF60: =stayWB[[#This Row],[out]]-stayWB[[#This Row],[in]] | BG60: =IF(BB60<>"",BG59+1,BG59) | BH60: . | BI60: FRA | BJ60: 1997 | BK60: =BI60 | BL60: =BJ60 | BM60: . | BN60: Z | BO60: =BN60 | BP60: . | BQ60: =IF(BR60<>"",BQ59+1,BQ59) | BR60: Lisbon | BS60: SSA | BT60: Lisbon-SSA | BU60: 34751 | BV60: . | BW60: =IF(BX60<>"",BW59+1,BW59) | CA60: =BZ60-BY60 | CB60: . | CC60: =IF(CD60<>"",CC59+1,CC59) | CD60: Salto Grande | CE60: 37441 | CF60: 37445 | CG60: =CF60-CE60 | CH60: . | CI60: =IF(CJ60<>"",CI59+1,CI59) | CJ60: 0 | CK60: .
